<?xml version="1.0"?>
<robot name="g1">
  <material name="dark">
    <color rgba="0.2 0.2 0.2 1"/>
  </material>
  <material name="white">
    <color rgba="0.7 0.7 0.7 1"/>
  </material>
  <link name="pelvis">
    <inertial>
      <origin xyz="0 0 -0.07605" rpy="0 0 0"/>
      <mass value="3.813"/>
      <inertia ixx="0.010549" ixy="0" ixz="2.1E-06" iyy="0.0093089" iyz="0" izz="0.0079184"/>
    </inertial>
    <visual>
      <geometry>
        <mesh filename="g1/assets/visuals/pelvis.STL"/>
      </geometry>
      <material name="dark"/>
    </visual>
    <collision name="pelvis">
      <geometry>
        <mesh filename="g1/assets/collisions/pelvis_collision.STL"/>
      </geometry>
    </collision>
    <collision_checking>
      <convex name="pelvis"/>
    </collision_checking>
  </link>
  <link name="pelvis_contour_link">
    <inertial>
      <mass value="0.001"/>
      <inertia ixx="1e-7" ixy="0" ixz="0" iyy="1e-7" iyz="0" izz="1e-7"/>
    </inertial>
    <visual>
      <geometry>
        <mesh filename="g1/assets/visuals/pelvis_contour_link.STL"/>
      </geometry>
      <material name="white"/>
    </visual>
  </link>
  <joint name="pelvis_contour_joint" type="fixed">
    <parent link="pelvis"/>
    <child link="pelvis_contour_link"/>
  </joint>
  <!-- Legs -->
  <link name="left_hip_pitch_link">
    <inertial>
      <origin xyz="0.002741 0.047791 -0.02606" rpy="0 0 0"/>
      <mass value="1.35"/>
      <inertia ixx="0.001811" ixy="3.68E-05" ixz="-3.44E-05" iyy="0.0014193" iyz="0.000171" izz="0.0012812"/>
    </inertial>
    <visual>
      <geometry>
        <mesh filename="g1/assets/visuals/left_hip_pitch_link.STL"/>
      </geometry>
      <material name="dark"/>
    </visual>
    <collision name="left_hip_pitch_link">
      <geometry>
        <mesh filename="g1/assets/collisions/left_hip_pitch_link_collision.STL"/>
      </geometry>
    </collision>
    <collision_checking>
      <convex name="left_hip_pitch_link"/>
    </collision_checking>
  </link>
  <joint name="left_hip_pitch_joint" type="revolute">
    <origin xyz="0 0.064452 -0.1027" rpy="0 0 0"/>
    <parent link="pelvis"/>
    <child link="left_hip_pitch_link"/>
    <axis xyz="0 1 0"/>
    <limit lower="-2.5307" upper="2.8798" effort="88" velocity="32"/>
  </joint>
  <link name="left_hip_roll_link">
    <inertial>
      <origin xyz="0.029812 -0.001045 -0.087934" rpy="0 0 0"/>
      <mass value="1.52"/>
      <inertia ixx="0.0023773" ixy="-3.8E-06" ixz="-0.0003908" iyy="0.0024123" iyz="1.84E-05" izz="0.0016595"/>
    </inertial>
    <visual>
      <geometry>
        <mesh filename="g1/assets/visuals/left_hip_roll_link.STL"/>
      </geometry>
      <material name="white"/>
    </visual>
    <collision name="left_hip_roll_link">
      <geometry>
        <mesh filename="g1/assets/collisions/left_hip_roll_link_collision.STL"/>
      </geometry>
    </collision>
    <collision_checking>
      <convex name="left_hip_roll_link"/>
    </collision_checking>
  </link>
  <joint name="left_hip_roll_joint" type="revolute">
    <origin xyz="0 0.052 -0.030465" rpy="0 -0.1749 0"/>
    <parent link="left_hip_pitch_link"/>
    <child link="left_hip_roll_link"/>
    <axis xyz="1 0 0"/>
    <limit lower="-0.5236" upper="2.9671" effort="139" velocity="20"/>
  </joint>
  <link name="left_hip_yaw_link">
    <inertial>
      <origin xyz="-0.057709 -0.010981 -0.15078" rpy="0 0 0"/>
      <mass value="1.702"/>
      <inertia ixx="0.0057774" ixy="-0.0005411" ixz="-0.0023948" iyy="0.0076124" iyz="-0.0007072" izz="0.003149"/>
    </inertial>
    <visual>
      <geometry>
        <mesh filename="g1/assets/visuals/left_hip_yaw_link.STL"/>
      </geometry>
      <material name="white"/>
    </visual>
    <collision name="left_hip_yaw_link">
      <geometry>
        <mesh filename="g1/assets/collisions/left_hip_yaw_link_collision.STL"/>
      </geometry>
    </collision>
    <collision_checking>
      <convex name="left_hip_yaw_link"/>
    </collision_checking>
  </link>
  <joint name="left_hip_yaw_joint" type="revolute">
    <origin xyz="0.025001 0 -0.12412" rpy="0 0 0"/>
    <parent link="left_hip_roll_link"/>
    <child link="left_hip_yaw_link"/>
    <axis xyz="0 0 1"/>
    <limit lower="-2.7576" upper="2.7576" effort="88" velocity="32"/>
  </joint>
  <link name="left_knee_link">
    <inertial>
      <origin xyz="0.005457 0.003964 -0.12074" rpy="0 0 0"/>
      <mass value="1.932"/>
      <inertia ixx="0.011329" ixy="4.82E-05" ixz="-4.49E-05" iyy="0.011277" iyz="-0.0007146" izz="0.0015168"/>
    </inertial>
    <visual>
      <geometry>
        <mesh filename="g1/assets/visuals/left_knee_link.STL"/>
      </geometry>
      <material name="white"/>
    </visual>
    <collision name="left_knee_link">
      <geometry>
        <mesh filename="g1/assets/collisions/left_knee_link_collision.STL"/>
      </geometry>
    </collision>
    <collision_checking>
      <convex name="left_knee_link"/>
    </collision_checking>
  </link>
  <joint name="left_knee_joint" type="revolute">
    <origin xyz="-0.078273 0.0021489 -0.17734" rpy="0 0.1749 0"/>
    <parent link="left_hip_yaw_link"/>
    <child link="left_knee_link"/>
    <axis xyz="0 1 0"/>
    <limit lower="-0.087267" upper="2.8798" effort="139" velocity="20"/>
  </joint>
  <link name="left_ankle_pitch_link">
    <inertial>
      <origin xyz="-0.007269 0 0.011137" rpy="0 0 0"/>
      <mass value="0.074"/>
      <inertia ixx="8.4E-06" ixy="0" ixz="-2.9E-06" iyy="1.89E-05" iyz="0" izz="1.26E-05"/>
    </inertial>
    <visual>
      <geometry>
        <mesh filename="g1/assets/visuals/left_ankle_pitch_link.STL"/>
      </geometry>
      <material name="white"/>
    </visual>
  </link>
  <joint name="left_ankle_pitch_joint" type="revolute">
    <origin xyz="0 -9.4445E-05 -0.30001" rpy="0 0 0"/>
    <parent link="left_knee_link"/>
    <child link="left_ankle_pitch_link"/>
    <axis xyz="0 1 0"/>
    <limit lower="-0.87267" upper="0.5236" effort="35" velocity="30"/>
  </joint>
  <link name="left_ankle_roll_link">
    <inertial>
      <origin xyz="0.026505 0 -0.016425" rpy="0 0 0"/>
      <mass value="0.608"/>
      <inertia ixx="0.0002231" ixy="2E-07" ixz="8.91E-05" iyy="0.0016161" iyz="-1E-07" izz="0.0016667"/>
    </inertial>
    <visual>
      <geometry>
        <mesh filename="g1/assets/visuals/left_ankle_roll_link.STL"/>
      </geometry>
      <material name="dark"/>
    </visual>
    <collision name="left_ankle_roll_link">
      <geometry>
        <mesh filename="g1/assets/collisions/left_ankle_roll_link_collision.STL"/>
      </geometry>
    </collision>
    <collision_checking>
      <convex name="left_ankle_roll_link"/>
    </collision_checking>
  </link>
  <joint name="left_ankle_roll_joint" type="revolute">
    <origin xyz="0 0 -0.017558" rpy="0 0 0"/>
    <parent link="left_ankle_pitch_link"/>
    <child link="left_ankle_roll_link"/>
    <axis xyz="1 0 0"/>
    <limit lower="-0.2618" upper="0.2618" effort="35" velocity="30"/>
  </joint>
  <link name="right_hip_pitch_link">
    <inertial>
      <origin xyz="0.002741 -0.047791 -0.02606" rpy="0 0 0"/>
      <mass value="1.35"/>
      <inertia ixx="0.001811" ixy="-3.68E-05" ixz="-3.44E-05" iyy="0.0014193" iyz="-0.000171" izz="0.0012812"/>
    </inertial>
    <visual>
      <geometry>
        <mesh filename="g1/assets/visuals/right_hip_pitch_link.STL"/>
      </geometry>
      <material name="dark"/>
    </visual>
    <collision name="right_hip_pitch_link">
      <geometry>
        <mesh filename="g1/assets/collisions/right_hip_pitch_link_collision.STL"/>
      </geometry>
    </collision>
    <collision_checking>
      <convex name="right_hip_pitch_link"/>
    </collision_checking>
  </link>
  <joint name="right_hip_pitch_joint" type="revolute">
    <origin xyz="0 -0.064452 -0.1027" rpy="0 0 0"/>
    <parent link="pelvis"/>
    <child link="right_hip_pitch_link"/>
    <axis xyz="0 1 0"/>
    <limit lower="-2.5307" upper="2.8798" effort="88" velocity="32"/>
  </joint>
  <link name="right_hip_roll_link">
    <inertial>
      <origin xyz="0.029812 0.001045 -0.087934" rpy="0 0 0"/>
      <mass value="1.52"/>
      <inertia ixx="0.0023773" ixy="3.8E-06" ixz="-0.0003908" iyy="0.0024123" iyz="-1.84E-05" izz="0.0016595"/>
    </inertial>
    <visual>
      <geometry>
        <mesh filename="g1/assets/visuals/right_hip_roll_link.STL"/>
      </geometry>
      <material name="white"/>
    </visual>
    <collision name="right_hip_roll_link">
      <geometry>
        <mesh filename="g1/assets/collisions/right_hip_roll_link_collision.STL"/>
      </geometry>
    </collision>
    <collision_checking>
      <convex name="right_hip_roll_link"/>
    </collision_checking>
  </link>
  <joint name="right_hip_roll_joint" type="revolute">
    <origin xyz="0 -0.052 -0.030465" rpy="0 -0.1749 0"/>
    <parent link="right_hip_pitch_link"/>
    <child link="right_hip_roll_link"/>
    <axis xyz="1 0 0"/>
    <limit lower="-2.9671" upper="0.5236" effort="139" velocity="20"/>
  </joint>
  <link name="right_hip_yaw_link">
    <inertial>
      <origin xyz="-0.057709 0.010981 -0.15078" rpy="0 0 0"/>
      <mass value="1.702"/>
      <inertia ixx="0.0057774" ixy="0.0005411" ixz="-0.0023948" iyy="0.0076124" iyz="0.0007072" izz="0.003149"/>
    </inertial>
    <visual>
      <geometry>
        <mesh filename="g1/assets/visuals/right_hip_yaw_link.STL"/>
      </geometry>
      <material name="white"/>
    </visual>
    <collision name="right_hip_yaw_link">
      <geometry>
        <mesh filename="g1/assets/collisions/right_hip_yaw_link_collision.STL"/>
      </geometry>
    </collision>
    <collision_checking>
      <convex name="right_hip_yaw_link"/>
    </collision_checking>
  </link>
  <joint name="right_hip_yaw_joint" type="revolute">
    <origin xyz="0.025001 0 -0.12412" rpy="0 0 0"/>
    <parent link="right_hip_roll_link"/>
    <child link="right_hip_yaw_link"/>
    <axis xyz="0 0 1"/>
    <limit lower="-2.7576" upper="2.7576" effort="88" velocity="32"/>
  </joint>
  <link name="right_knee_link">
    <inertial>
      <origin xyz="0.005457 -0.003964 -0.12074" rpy="0 0 0"/>
      <mass value="1.932"/>
      <inertia ixx="0.011329" ixy="-4.82E-05" ixz="4.49E-05" iyy="0.011277" iyz="0.0007146" izz="0.0015168"/>
    </inertial>
    <visual>
      <geometry>
        <mesh filename="g1/assets/visuals/right_knee_link.STL"/>
      </geometry>
      <material name="white"/>
    </visual>
    <collision name="right_knee_link">
      <geometry>
        <mesh filename="g1/assets/collisions/right_knee_link_collision.STL"/>
      </geometry>
    </collision>
    <collision_checking>
      <convex name="right_knee_link"/>
    </collision_checking>
  </link>
  <joint name="right_knee_joint" type="revolute">
    <origin xyz="-0.078273 -0.0021489 -0.17734" rpy="0 0.1749 0"/>
    <parent link="right_hip_yaw_link"/>
    <child link="right_knee_link"/>
    <axis xyz="0 1 0"/>
    <limit lower="-0.087267" upper="2.8798" effort="139" velocity="20"/>
  </joint>
  <link name="right_ankle_pitch_link">
    <inertial>
      <origin xyz="-0.007269 0 0.011137" rpy="0 0 0"/>
      <mass value="0.074"/>
      <inertia ixx="8.4E-06" ixy="0" ixz="-2.9E-06" iyy="1.89E-05" iyz="0" izz="1.26E-05"/>
    </inertial>
    <visual>
      <geometry>
        <mesh filename="g1/assets/visuals/right_ankle_pitch_link.STL"/>
      </geometry>
      <material name="white"/>
    </visual>
  </link>
  <joint name="right_ankle_pitch_joint" type="revolute">
    <origin xyz="0 9.4445E-05 -0.30001" rpy="0 0 0"/>
    <parent link="right_knee_link"/>
    <child link="right_ankle_pitch_link"/>
    <axis xyz="0 1 0"/>
    <limit lower="-0.87267" upper="0.5236" effort="35" velocity="30"/>
  </joint>
  <link name="right_ankle_roll_link">
    <inertial>
      <origin xyz="0.026505 0 -0.016425" rpy="0 0 0"/>
      <mass value="0.608"/>
      <inertia ixx="0.0002231" ixy="-2E-07" ixz="8.91E-05" iyy="0.0016161" iyz="1E-07" izz="0.0016667"/>
    </inertial>
    <visual>
      <geometry>
        <mesh filename="g1/assets/visuals/right_ankle_roll_link.STL"/>
      </geometry>
      <material name="dark"/>
    </visual>
    <collision name="right_ankle_roll_link">
      <geometry>
        <mesh filename="g1/assets/collisions/right_ankle_roll_link_collision.STL"/>
      </geometry>
    </collision>
    <collision_checking>
      <convex name="right_ankle_roll_link"/>
    </collision_checking>
  </link>
  <joint name="right_ankle_roll_joint" type="revolute">
    <origin xyz="0 0 -0.017558" rpy="0 0 0"/>
    <parent link="right_ankle_pitch_link"/>
    <child link="right_ankle_roll_link"/>
    <axis xyz="1 0 0"/>
    <limit lower="-0.2618" upper="0.2618" effort="35" velocity="30"/>
  </joint>
  <!-- Torso -->
  <link name="waist_yaw_link">
    <inertial>
      <origin xyz="0.003494 0.000233 0.018034" rpy="0 0 0"/>
      <mass value="0.214"/>
      <inertia ixx="0.00010673" ixy="2.703E-06" ixz="-7.631E-06" iyy="0.00010422" iyz="-2.01E-07" izz="0.0001625"/>
    </inertial>
    <visual>
      <geometry>
        <mesh filename="g1/assets/visuals/waist_yaw_link_rev_1_0.STL"/>
      </geometry>
      <material name="white"/>
    </visual>
  </link>
  <joint name="waist_yaw_joint" type="revolute">
    <parent link="pelvis"/>
    <child link="waist_yaw_link"/>
    <axis xyz="0 0 1"/>
    <limit lower="-2.618" upper="2.618" effort="88" velocity="32"/>
  </joint>
  <link name="waist_roll_link">
    <inertial>
      <origin xyz="0 2.3E-05 0" rpy="0 0 0"/>
      <mass value="0.086"/>
      <inertia ixx="7.079E-06" ixy="0" ixz="0" iyy="6.339E-06" iyz="0" izz="8.245E-06"/>
    </inertial>
    <visual>
      <geometry>
        <mesh filename="g1/assets/visuals/waist_roll_link_rev_1_0.STL"/>
      </geometry>
      <material name="white"/>
    </visual>
  </link>
  <joint name="waist_roll_joint" type="fixed">
    <origin xyz="-0.0039635 0 0.044" rpy="0 0 0"/>
    <parent link="waist_yaw_link"/>
    <child link="waist_roll_link"/>
    <axis xyz="1 0 0"/>
    <limit lower="-0.52" upper="0.52" effort="35" velocity="30"/>
  </joint>
  <link name="torso_link">
    <inertial>
      <origin xyz="0.000931 0.000346 0.15082" rpy="0 0 0"/>
      <mass value="6.78"/>
      <inertia ixx="0.05905" ixy="3.3302E-05" ixz="-0.0017715" iyy="0.047014" iyz="-2.2399E-05" izz="0.025652"/>
    </inertial>
    <visual>
      <geometry>
        <mesh filename="g1/assets/visuals/torso_link_rev_1_0.STL"/>
      </geometry>
      <material name="white"/>
    </visual>
    <collision name="torso_link">
      <geometry>
        <mesh filename="g1/assets/collisions/torso_waist_roll_pitch_collision.STL"/>
      </geometry>
    </collision>
    <collision_checking>
      <convex name="torso_link"/>
    </collision_checking>
  </link>
  <joint name="waist_pitch_joint" type="fixed">
    <parent link="waist_roll_link"/>
    <child link="torso_link"/>
    <axis xyz="0 1 0"/>
    <limit lower="-0.52" upper="0.52" effort="35" velocity="30"/>
  </joint>
  <!-- LOGO -->
  <joint name="logo_joint" type="fixed">
    <origin xyz="0.0039635 0 -0.044" rpy="0 0 0"/>
    <parent link="torso_link"/>
    <child link="logo_link"/>
  </joint>
  <link name="logo_link">
    <inertial>
      <mass value="0.001"/>
      <inertia ixx="1e-7" ixy="0" ixz="0" iyy="1e-7" iyz="0" izz="1e-7"/>
    </inertial>
    <visual>
      <geometry>
        <mesh filename="g1/assets/visuals/logo_link.STL"/>
      </geometry>
      <material name="dark"/>
    </visual>
  </link>
  <!-- Head -->
  <link name="head_link">
    <inertial>
      <origin xyz="0.005267 0.000299 0.449869" rpy="0 0 0"/>
      <mass value="1.036"/>
      <inertia ixx="0.004085051" ixy="-2.543E-06" ixz="-6.9455E-05" iyy="0.004185212" iyz="-3.726E-06" izz="0.001807911"/>
    </inertial>
    <visual>
      <geometry>
        <mesh filename="g1/assets/visuals/head_link.STL"/>
      </geometry>
      <material name="dark"/>
    </visual>
    <collision name="head_link">
      <geometry>
        <mesh filename="g1/assets/collisions/head_link_collision.STL"/>
      </geometry>
    </collision>
    <collision_checking>
      <convex name="head_link"/>
    </collision_checking>
  </link>
  <joint name="head_joint" type="fixed">
    <origin xyz="0.0039635 0 -0.044" rpy="0 0 0"/>
    <parent link="torso_link"/>
    <child link="head_link"/>
  </joint>
  <!-- IMU -->
  <link name="imu_in_torso"/>
  <joint name="imu_in_torso_joint" type="fixed">
    <origin xyz="-0.03959 -0.00224 0.14792" rpy="0 0 0"/>
    <parent link="torso_link"/>
    <child link="imu_in_torso"/>
  </joint>
  <link name="imu_in_pelvis"/>
  <joint name="imu_in_pelvis_joint" type="fixed">
    <origin xyz="0.04525 0 -0.08339" rpy="0 0 0"/>
    <parent link="pelvis"/>
    <child link="imu_in_pelvis"/>
  </joint>
  <!-- d435 -->
  <link name="d435_link"/>
  <joint name="d435_joint" type="fixed">
    <origin xyz="0.0576235 0.01753 0.42987" rpy="0 0.8307767239493009 0"/>
    <parent link="torso_link"/>
    <child link="d435_link"/>
  </joint>
  <!-- battery -->
  <link name="battery">
    <inertial>
      <mass value="2.5"/>
      <inertia ixx="0.00975" ixy="0.0" ixz="0.0" iyy="0.004333333" iyz="0.0" izz="0.008083333"/>
    </inertial>
  </link>
  <joint name="battery_joint" type="fixed">
    <origin xyz="0.05 0.025 -0.01" rpy="0 0 0"/>
    <parent link="imu_in_torso"/>
    <child link="battery"/>
  </joint>
  <!-- mid360 -->
  <link name="mid360_link"/>
  <joint name="mid360_joint" type="fixed">
    <origin xyz="0.0002835 0.00003 0.41618" rpy="0 0.04014257279586953 0"/>
    <parent link="torso_link"/>
    <child link="mid360_link"/>
  </joint>
  <!-- Arm -->
  <link name="left_shoulder_pitch_link">
    <inertial>
      <origin xyz="0 0.035892 -0.011628" rpy="0 0 0"/>
      <mass value="0.718"/>
      <inertia ixx="0.0004291" ixy="-9.2E-06" ixz="6.4E-06" iyy="0.000453" iyz="2.26E-05" izz="0.000423"/>
    </inertial>
    <visual>
      <geometry>
        <mesh filename="g1/assets/visuals/left_shoulder_pitch_link.STL"/>
      </geometry>
      <material name="white"/>
    </visual>
    <collision name="left_shoulder_pitch_link">
      <geometry>
        <mesh filename="g1/assets/collisions/left_shoulder_pitch_link_collision.STL"/>
      </geometry>
    </collision>
    <collision_checking>
      <convex name="left_shoulder_pitch_link"/>
    </collision_checking>
  </link>
  <joint name="left_shoulder_pitch_joint" type="revolute">
    <origin xyz="0.0039563 0.10022 0.24778" rpy="0.27931 5.4949E-05 -0.00019159"/>
    <parent link="torso_link"/>
    <child link="left_shoulder_pitch_link"/>
    <axis xyz="0 1 0"/>
    <limit lower="-3.0892" upper="2.6704" effort="25" velocity="37"/>
  </joint>
  <link name="left_shoulder_roll_link">
    <inertial>
      <origin xyz="-0.000227 0.00727 -0.063243" rpy="0 0 0"/>
      <mass value="0.643"/>
      <inertia ixx="0.0006177" ixy="-1E-06" ixz="8.7E-06" iyy="0.0006912" iyz="-5.3E-06" izz="0.0003894"/>
    </inertial>
    <visual>
      <geometry>
        <mesh filename="g1/assets/visuals/left_shoulder_roll_link.STL"/>
      </geometry>
      <material name="white"/>
    </visual>
    <collision name="left_shoulder_roll_link">
      <geometry>
        <mesh filename="g1/assets/collisions/left_shoulder_roll_link_collision.STL"/>
      </geometry>
    </collision>
    <collision_checking>
      <convex name="left_shoulder_roll_link"/>
    </collision_checking>
  </link>
  <joint name="left_shoulder_roll_joint" type="revolute">
    <origin xyz="0 0.038 -0.013831" rpy="-0.27925 0 0"/>
    <parent link="left_shoulder_pitch_link"/>
    <child link="left_shoulder_roll_link"/>
    <axis xyz="1 0 0"/>
    <limit lower="-1.5882" upper="2.2515" effort="25" velocity="37"/>
  </joint>
  <link name="left_shoulder_yaw_link">
    <inertial>
      <origin xyz="0.010773 -0.002949 -0.072009" rpy="0 0 0"/>
      <mass value="0.734"/>
      <inertia ixx="0.0009988" ixy="7.9E-06" ixz="0.0001412" iyy="0.0010605" iyz="-2.86E-05" izz="0.0004354"/>
    </inertial>
    <visual>
      <geometry>
        <mesh filename="g1/assets/visuals/left_shoulder_yaw_link.STL"/>
      </geometry>
      <material name="white"/>
    </visual>
    <collision name="left_shoulder_yaw_link">
      <geometry>
        <mesh filename="g1/assets/collisions/left_shoulder_yaw_link_collision.STL"/>
      </geometry>
    </collision>
    <collision_checking>
      <convex name="left_shoulder_yaw_link"/>
    </collision_checking>
  </link>
  <joint name="left_shoulder_yaw_joint" type="revolute">
    <origin xyz="0 0.00624 -0.1032" rpy="0 0 0"/>
    <parent link="left_shoulder_roll_link"/>
    <child link="left_shoulder_yaw_link"/>
    <axis xyz="0 0 1"/>
    <limit lower="-2.618" upper="2.618" effort="25" velocity="37"/>
  </joint>
  <link name="left_elbow_link">
    <inertial>
      <origin xyz="0.064956 0.004454 -0.010062" rpy="0 0 0"/>
      <mass value="0.6"/>
      <inertia ixx="0.0002891" ixy="6.53E-05" ixz="1.72E-05" iyy="0.0004152" iyz="-5.6E-06" izz="0.0004197"/>
    </inertial>
    <visual>
      <geometry>
        <mesh filename="g1/assets/visuals/left_elbow_link.STL"/>
      </geometry>
      <material name="white"/>
    </visual>
    <collision name="left_elbow_link">
      <geometry>
        <mesh filename="g1/assets/collisions/left_elbow_link_collision.STL"/>
      </geometry>
    </collision>
    <collision_checking>
      <convex name="left_elbow_link"/>
    </collision_checking>
  </link>
  <joint name="left_elbow_joint" type="revolute">
    <origin xyz="0.015783 0 -0.080518" rpy="0 0 0"/>
    <parent link="left_shoulder_yaw_link"/>
    <child link="left_elbow_link"/>
    <axis xyz="0 1 0"/>
    <limit lower="-1.0472" upper="2.0944" effort="25" velocity="37"/>
  </joint>
  <joint name="left_wrist_roll_joint" type="revolute">
    <origin xyz="0.100 0.00188791 -0.010" rpy="0 0 0"/>
    <axis xyz="1 0 0"/>
    <parent link="left_elbow_link"/>
    <child link="left_wrist_roll_link"/>
    <limit effort="25" velocity="37" lower="-1.972222054" upper="1.972222054"/>
  </joint>
  <link name="left_wrist_roll_link">
    <inertial>
      <origin xyz="0.01713944778 0.00053759094 0.00000048864" rpy="0 0 0"/>
      <mass value="0.08544498"/>
      <inertia ixx="0.00004821544023" ixy="-0.00000424511021" ixz="0.00000000510599" iyy="0.00003722899093" iyz="-0.00000000123525" izz="0.00005482106541"/>
    </inertial>
    <visual>
      <geometry>
        <mesh filename="g1/assets/visuals/left_wrist_roll_link.STL"/>
      </geometry>
      <material name="white"/>
    </visual>
    <collision name="left_wrist_roll_link">
      <geometry>
        <mesh filename="g1/assets/collisions/left_wrist_roll_link_collision.STL"/>
      </geometry>
    </collision>
    <collision_checking>
      <convex name="left_wrist_roll_link"/>
    </collision_checking>
  </link>
  <joint name="left_wrist_pitch_joint" type="revolute">
    <origin xyz="0.038 0 0" rpy="0 0 0"/>
    <axis xyz="0 1 0"/>
    <parent link="left_wrist_roll_link"/>
    <child link="left_wrist_pitch_link"/>
    <limit effort="5" velocity="22" lower="-1.614429558" upper="1.614429558"/>
  </joint>
  <link name="left_wrist_pitch_link">
    <inertial>
      <origin xyz="0.02299989837 -0.00111685314 -0.00111658096" rpy="0 0 0"/>
      <mass value="0.48404956"/>
      <inertia ixx="0.00016579646273" ixy="-0.00001231206746" ixz="0.00001231699194" iyy="0.00042954057410" iyz="0.00000081417712" izz="0.00042953697654"/>
    </inertial>
    <visual>
      <geometry>
        <mesh filename="g1/assets/visuals/left_wrist_pitch_link.STL"/>
      </geometry>
      <material name="white"/>
    </visual>
    <collision name="left_wrist_pitch_link">
      <geometry>
        <mesh filename="g1/assets/collisions/left_wrist_pitch_link_collision.STL"/>
      </geometry>
    </collision>
    <collision_checking>
      <convex name="left_wrist_pitch_link"/>
    </collision_checking>
  </link>
  <joint name="left_wrist_yaw_joint" type="revolute">
    <origin xyz="0.046 0 0" rpy="0 0 0"/>
    <axis xyz="0 0 1"/>
    <parent link="left_wrist_pitch_link"/>
    <child link="left_wrist_yaw_link"/>
    <limit effort="5" velocity="22" lower="-1.614429558" upper="1.614429558"/>
  </joint>
  <link name="left_wrist_yaw_link">
    <inertial>
      <origin xyz="0.02200381568 0.00049485096 0.00053861123" rpy="0 0 0"/>
      <mass value="0.08457647"/>
      <inertia ixx="0.00004929128828" ixy="-0.00000045735494" ixz="0.00000445867591" iyy="0.00005973338134" iyz="0.00000043217198" izz="0.00003928083826"/>
    </inertial>
    <visual>
      <geometry>
        <mesh filename="g1/assets/visuals/left_wrist_yaw_link.STL"/>
      </geometry>
      <material name="white"/>
    </visual>
  </link>
  <joint name="left_hand_palm_joint" type="fixed">
    <origin xyz="0.0415 0.003 0" rpy="0 0 0"/>
    <parent link="left_wrist_yaw_link"/>
    <child link="left_rubber_hand"/>
  </joint>
  <link name="left_rubber_hand">
    <inertial>
      <origin xyz="0.05361310808 -0.00295905240 0.00215413091" rpy="0 0 0"/>
      <mass value="0.170"/>
      <inertia ixx="0.00010099485234748" ixy="0.00003618590790516" ixz="-0.00000074301518642" iyy="0.00028135871571621" iyz="0.00000330189743286" izz="0.00021894770413514"/>
    </inertial>
    <visual>
      <geometry>
        <mesh filename="g1/assets/visuals/left_rubber_hand.STL"/>
      </geometry>
      <material name="white"/>
    </visual>
    <collision name="left_rubber_hand">
      <geometry>
        <mesh filename="g1/assets/collisions/left_wrist_hand_collision.STL"/>
      </geometry>
    </collision>
    <collision_checking>
      <convex name="left_rubber_hand"/>
    </collision_checking>
  </link>
  <link name="right_shoulder_pitch_link">
    <inertial>
      <origin xyz="0 -0.035892 -0.011628" rpy="0 0 0"/>
      <mass value="0.718"/>
      <inertia ixx="0.0004291" ixy="9.2E-06" ixz="6.4E-06" iyy="0.000453" iyz="-2.26E-05" izz="0.000423"/>
    </inertial>
    <visual>
      <geometry>
        <mesh filename="g1/assets/visuals/right_shoulder_pitch_link.STL"/>
      </geometry>
      <material name="white"/>
    </visual>
    <collision name="right_shoulder_pitch_link">
      <geometry>
        <mesh filename="g1/assets/collisions/right_shoulder_pitch_link_collision.STL"/>
      </geometry>
    </collision>
    <collision_checking>
      <convex name="right_shoulder_pitch_link"/>
    </collision_checking>
  </link>
  <joint name="right_shoulder_pitch_joint" type="revolute">
    <origin xyz="0.0039563 -0.10021 0.24778" rpy="-0.27931 5.4949E-05 0.00019159"/>
    <parent link="torso_link"/>
    <child link="right_shoulder_pitch_link"/>
    <axis xyz="0 1 0"/>
    <limit lower="-3.0892" upper="2.6704" effort="25" velocity="37"/>
  </joint>
  <link name="right_shoulder_roll_link">
    <inertial>
      <origin xyz="-0.000227 -0.00727 -0.063243" rpy="0 0 0"/>
      <mass value="0.643"/>
      <inertia ixx="0.0006177" ixy="1E-06" ixz="8.7E-06" iyy="0.0006912" iyz="5.3E-06" izz="0.0003894"/>
    </inertial>
    <visual>
      <geometry>
        <mesh filename="g1/assets/visuals/right_shoulder_roll_link.STL"/>
      </geometry>
      <material name="white"/>
    </visual>
    <collision name="right_shoulder_roll_link">
      <geometry>
        <mesh filename="g1/assets/collisions/right_shoulder_roll_link_collision.STL"/>
      </geometry>
    </collision>
    <collision_checking>
      <convex name="right_shoulder_roll_link"/>
    </collision_checking>
  </link>
  <joint name="right_shoulder_roll_joint" type="revolute">
    <origin xyz="0 -0.038 -0.013831" rpy="0.27925 0 0"/>
    <parent link="right_shoulder_pitch_link"/>
    <child link="right_shoulder_roll_link"/>
    <axis xyz="1 0 0"/>
    <limit lower="-2.2515" upper="1.5882" effort="25" velocity="37"/>
  </joint>
  <link name="right_shoulder_yaw_link">
    <inertial>
      <origin xyz="0.010773 0.002949 -0.072009" rpy="0 0 0"/>
      <mass value="0.734"/>
      <inertia ixx="0.0009988" ixy="-7.9E-06" ixz="0.0001412" iyy="0.0010605" iyz="2.86E-05" izz="0.0004354"/>
    </inertial>
    <visual>
      <geometry>
        <mesh filename="g1/assets/visuals/right_shoulder_yaw_link.STL"/>
      </geometry>
      <material name="white"/>
    </visual>
    <collision name="right_shoulder_yaw_link">
      <geometry>
        <mesh filename="g1/assets/collisions/right_shoulder_yaw_link_collision.STL"/>
      </geometry>
    </collision>
    <collision_checking>
      <convex name="right_shoulder_yaw_link"/>
    </collision_checking>
  </link>
  <joint name="right_shoulder_yaw_joint" type="revolute">
    <origin xyz="0 -0.00624 -0.1032" rpy="0 0 0"/>
    <parent link="right_shoulder_roll_link"/>
    <child link="right_shoulder_yaw_link"/>
    <axis xyz="0 0 1"/>
    <limit lower="-2.618" upper="2.618" effort="25" velocity="37"/>
  </joint>
  <link name="right_elbow_link">
    <inertial>
      <origin xyz="0.064956 -0.004454 -0.010062" rpy="0 0 0"/>
      <mass value="0.6"/>
      <inertia ixx="0.0002891" ixy="-6.53E-05" ixz="1.72E-05" iyy="0.0004152" iyz="5.6E-06" izz="0.0004197"/>
    </inertial>
    <visual>
      <geometry>
        <mesh filename="g1/assets/visuals/right_elbow_link.STL"/>
      </geometry>
      <material name="white"/>
    </visual>
    <collision name="right_elbow_link">
      <geometry>
        <mesh filename="g1/assets/collisions/right_elbow_link_collision.STL"/>
      </geometry>
    </collision>
    <collision_checking>
      <convex name="right_elbow_link"/>
    </collision_checking>
  </link>
  <joint name="right_elbow_joint" type="revolute">
    <origin xyz="0.015783 0 -0.080518" rpy="0 0 0"/>
    <parent link="right_shoulder_yaw_link"/>
    <child link="right_elbow_link"/>
    <axis xyz="0 1 0"/>
    <limit lower="-1.0472" upper="2.0944" effort="25" velocity="37"/>
  </joint>
  <joint name="right_wrist_roll_joint" type="revolute">
    <origin xyz="0.100 -0.00188791 -0.010" rpy="0 0 0"/>
    <axis xyz="1 0 0"/>
    <parent link="right_elbow_link"/>
    <child link="right_wrist_roll_link"/>
    <limit effort="25" velocity="37" lower="-1.972222054" upper="1.972222054"/>
  </joint>
  <link name="right_wrist_roll_link">
    <inertial>
      <origin xyz="0.01713944778 -0.00053759094 0.00000048864" rpy="0 0 0"/>
      <mass value="0.08544498"/>
      <inertia ixx="0.00004821544023" ixy="0.00000424511021" ixz="0.00000000510599" iyy="0.00003722899093" iyz="0.00000000123525" izz="0.00005482106541"/>
    </inertial>
    <visual>
      <geometry>
        <mesh filename="g1/assets/visuals/right_wrist_roll_link.STL"/>
      </geometry>
      <material name="white"/>
    </visual>
    <collision name="right_wrist_roll_link">
      <geometry>
        <mesh filename="g1/assets/collisions/right_wrist_roll_link_collision.STL"/>
      </geometry>
    </collision>
    <collision_checking>
      <convex name="right_wrist_roll_link"/>
    </collision_checking>
  </link>
  <joint name="right_wrist_pitch_joint" type="revolute">
    <origin xyz="0.038 0 0" rpy="0 0 0"/>
    <axis xyz="0 1 0"/>
    <parent link="right_wrist_roll_link"/>
    <child link="right_wrist_pitch_link"/>
    <limit effort="5" velocity="22" lower="-1.614429558" upper="1.614429558"/>
  </joint>
  <link name="right_wrist_pitch_link">
    <inertial>
      <origin xyz="0.02299989837 0.00111685314 -0.00111658096" rpy="0 0 0"/>
      <mass value="0.48404956"/>
      <inertia ixx="0.00016579646273" ixy="0.00001231206746" ixz="0.00001231699194" iyy="0.00042954057410" iyz="-0.00000081417712" izz="0.00042953697654"/>
    </inertial>
    <visual>
      <geometry>
        <mesh filename="g1/assets/visuals/right_wrist_pitch_link.STL"/>
      </geometry>
      <material name="white"/>
    </visual>
    <collision name="right_wrist_pitch_link">
      <geometry>
        <mesh filename="g1/assets/collisions/right_wrist_pitch_link_collision.STL"/>
      </geometry>
    </collision>
    <collision_checking>
      <convex name="right_wrist_pitch_link"/>
    </collision_checking>
  </link>
  <joint name="right_wrist_yaw_joint" type="revolute">
    <origin xyz="0.046 0 0" rpy="0 0 0"/>
    <axis xyz="0 0 1"/>
    <parent link="right_wrist_pitch_link"/>
    <child link="right_wrist_yaw_link"/>
    <limit effort="5" velocity="22" lower="-1.614429558" upper="1.614429558"/>
  </joint>
  <link name="right_wrist_yaw_link">
    <inertial>
      <origin xyz="0.02200381568 -0.00049485096 0.00053861123" rpy="0 0 0"/>
      <mass value="0.08457647"/>
      <inertia ixx="0.00004929128828" ixy="0.00000045735494" ixz="0.00000445867591" iyy="0.00005973338134" iyz="-0.00000043217198" izz="0.00003928083826"/>
    </inertial>
    <visual>
      <geometry>
        <mesh filename="g1/assets/visuals/right_wrist_yaw_link.STL"/>
      </geometry>
      <material name="white"/>
    </visual>
  </link>
  <joint name="right_hand_palm_joint" type="fixed">
    <origin xyz="0.0415 -0.003 0" rpy="0 0 0"/>
    <parent link="right_wrist_yaw_link"/>
    <child link="right_rubber_hand"/>
  </joint>
  <link name="right_rubber_hand">
    <inertial>
      <origin xyz="0.05361310808 0.00295905240 0.00215413091" rpy="0 0 0"/>
      <mass value="0.170"/>
      <inertia ixx="0.00010099485234748" ixy="-0.00003618590790516" ixz="-0.00000074301518642" iyy="0.00028135871571621" iyz="-0.00000330189743286" izz="0.00021894770413514"/>
    </inertial>
    <visual>
      <geometry>
        <mesh filename="g1/assets/visuals/right_rubber_hand.STL"/>
      </geometry>
      <material name="white"/>
    </visual>
    <collision name="right_rubber_hand">
      <geometry>
        <mesh filename="g1/assets/collisions/right_wrist_hand_collision.STL"/>
      </geometry>
    </collision>
    <collision_checking>
      <convex name="right_rubber_hand"/>
    </collision_checking>
  </link>
</robot>
